vocabulary size: 80
n tunes: 1250
n train tunes: 1186
n validation tunes: 64
min, max length 38 1047
Train model
Embedding shape (64, ?, 80)
RNN output shape (64, ?, 512)
Reshape shape (?, 512)
Dense shape (?, 80)
Traceback (most recent call last):
  File "C:\Users\Sjoerd de Jong\anaconda3\envs\tensorFolk\lib\site-packages\tensorflow\python\client\session.py", line 1334, in _do_call
    return fn(*args)
  File "C:\Users\Sjoerd de Jong\anaconda3\envs\tensorFolk\lib\site-packages\tensorflow\python\client\session.py", line 1319, in _run_fn
    options, feed_dict, fetch_list, target_list, run_metadata)
  File "C:\Users\Sjoerd de Jong\anaconda3\envs\tensorFolk\lib\site-packages\tensorflow\python\client\session.py", line 1407, in _call_tf_sessionrun
    run_metadata)
tensorflow.python.framework.errors_impl.InvalidArgumentError: Assign requires shapes of both tensors to match. lhs shape= [80,80] rhs shape= [73,73]
	 [[{{node save/Assign_21}} = Assign[T=DT_FLOAT, _class=["loc:@w_emb"], use_locking=true, validate_shape=true, _device="/job:localhost/replica:0/task:0/device:CPU:0"](w_emb/RMSProp_1, save/RestoreV2:27)]]

During handling of the above exception, another exception occurred:

Traceback (most recent call last):
  File "C:\Users\Sjoerd de Jong\anaconda3\envs\tensorFolk\lib\site-packages\tensorflow\python\training\saver.py", line 1546, in restore
    {self.saver_def.filename_tensor_name: save_path})
  File "C:\Users\Sjoerd de Jong\anaconda3\envs\tensorFolk\lib\site-packages\tensorflow\python\client\session.py", line 929, in run
    run_metadata_ptr)
  File "C:\Users\Sjoerd de Jong\anaconda3\envs\tensorFolk\lib\site-packages\tensorflow\python\client\session.py", line 1152, in _run
    feed_dict_tensor, options, run_metadata)
  File "C:\Users\Sjoerd de Jong\anaconda3\envs\tensorFolk\lib\site-packages\tensorflow\python\client\session.py", line 1328, in _do_run
    run_metadata)
  File "C:\Users\Sjoerd de Jong\anaconda3\envs\tensorFolk\lib\site-packages\tensorflow\python\client\session.py", line 1348, in _do_call
    raise type(e)(node_def, op, message)
tensorflow.python.framework.errors_impl.InvalidArgumentError: Assign requires shapes of both tensors to match. lhs shape= [80,80] rhs shape= [73,73]
	 [[node save/Assign_21 (defined at train_rnn.py:114)  = Assign[T=DT_FLOAT, _class=["loc:@w_emb"], use_locking=true, validate_shape=true, _device="/job:localhost/replica:0/task:0/device:CPU:0"](w_emb/RMSProp_1, save/RestoreV2:27)]]

Caused by op 'save/Assign_21', defined at:
  File "train_rnn.py", line 114, in <module>
    saver = tf.train.Saver(max_to_keep=5)
  File "C:\Users\Sjoerd de Jong\anaconda3\envs\tensorFolk\lib\site-packages\tensorflow\python\training\saver.py", line 1102, in __init__
    self.build()
  File "C:\Users\Sjoerd de Jong\anaconda3\envs\tensorFolk\lib\site-packages\tensorflow\python\training\saver.py", line 1114, in build
    self._build(self._filename, build_save=True, build_restore=True)
  File "C:\Users\Sjoerd de Jong\anaconda3\envs\tensorFolk\lib\site-packages\tensorflow\python\training\saver.py", line 1151, in _build
    build_save=build_save, build_restore=build_restore)
  File "C:\Users\Sjoerd de Jong\anaconda3\envs\tensorFolk\lib\site-packages\tensorflow\python\training\saver.py", line 795, in _build_internal
    restore_sequentially, reshape)
  File "C:\Users\Sjoerd de Jong\anaconda3\envs\tensorFolk\lib\site-packages\tensorflow\python\training\saver.py", line 428, in _AddRestoreOps
    assign_ops.append(saveable.restore(saveable_tensors, shapes))
  File "C:\Users\Sjoerd de Jong\anaconda3\envs\tensorFolk\lib\site-packages\tensorflow\python\training\saver.py", line 119, in restore
    self.op.get_shape().is_fully_defined())
  File "C:\Users\Sjoerd de Jong\anaconda3\envs\tensorFolk\lib\site-packages\tensorflow\python\ops\state_ops.py", line 221, in assign
    validate_shape=validate_shape)
  File "C:\Users\Sjoerd de Jong\anaconda3\envs\tensorFolk\lib\site-packages\tensorflow\python\ops\gen_state_ops.py", line 64, in assign
    use_locking=use_locking, name=name)
  File "C:\Users\Sjoerd de Jong\anaconda3\envs\tensorFolk\lib\site-packages\tensorflow\python\framework\op_def_library.py", line 787, in _apply_op_helper
    op_def=op_def)
  File "C:\Users\Sjoerd de Jong\anaconda3\envs\tensorFolk\lib\site-packages\tensorflow\python\util\deprecation.py", line 488, in new_func
    return func(*args, **kwargs)
  File "C:\Users\Sjoerd de Jong\anaconda3\envs\tensorFolk\lib\site-packages\tensorflow\python\framework\ops.py", line 3274, in create_op
    op_def=op_def)
  File "C:\Users\Sjoerd de Jong\anaconda3\envs\tensorFolk\lib\site-packages\tensorflow\python\framework\ops.py", line 1770, in __init__
    self._traceback = tf_stack.extract_stack()

InvalidArgumentError (see above for traceback): Assign requires shapes of both tensors to match. lhs shape= [80,80] rhs shape= [73,73]
	 [[node save/Assign_21 (defined at train_rnn.py:114)  = Assign[T=DT_FLOAT, _class=["loc:@w_emb"], use_locking=true, validate_shape=true, _device="/job:localhost/replica:0/task:0/device:CPU:0"](w_emb/RMSProp_1, save/RestoreV2:27)]]


During handling of the above exception, another exception occurred:

Traceback (most recent call last):
  File "train_rnn.py", line 134, in <module>
    saver.restore(sess, os.path.join(metadata_target_path, ckpt_name))
  File "C:\Users\Sjoerd de Jong\anaconda3\envs\tensorFolk\lib\site-packages\tensorflow\python\training\saver.py", line 1582, in restore
    err, "a mismatch between the current graph and the graph")
tensorflow.python.framework.errors_impl.InvalidArgumentError: Restoring from checkpoint failed. This is most likely due to a mismatch between the current graph and the graph from the checkpoint. Please ensure that you have not altered the graph expected based on the checkpoint. Original error:

Assign requires shapes of both tensors to match. lhs shape= [80,80] rhs shape= [73,73]
	 [[node save/Assign_21 (defined at train_rnn.py:114)  = Assign[T=DT_FLOAT, _class=["loc:@w_emb"], use_locking=true, validate_shape=true, _device="/job:localhost/replica:0/task:0/device:CPU:0"](w_emb/RMSProp_1, save/RestoreV2:27)]]

Caused by op 'save/Assign_21', defined at:
  File "train_rnn.py", line 114, in <module>
    saver = tf.train.Saver(max_to_keep=5)
  File "C:\Users\Sjoerd de Jong\anaconda3\envs\tensorFolk\lib\site-packages\tensorflow\python\training\saver.py", line 1102, in __init__
    self.build()
  File "C:\Users\Sjoerd de Jong\anaconda3\envs\tensorFolk\lib\site-packages\tensorflow\python\training\saver.py", line 1114, in build
    self._build(self._filename, build_save=True, build_restore=True)
  File "C:\Users\Sjoerd de Jong\anaconda3\envs\tensorFolk\lib\site-packages\tensorflow\python\training\saver.py", line 1151, in _build
    build_save=build_save, build_restore=build_restore)
  File "C:\Users\Sjoerd de Jong\anaconda3\envs\tensorFolk\lib\site-packages\tensorflow\python\training\saver.py", line 795, in _build_internal
    restore_sequentially, reshape)
  File "C:\Users\Sjoerd de Jong\anaconda3\envs\tensorFolk\lib\site-packages\tensorflow\python\training\saver.py", line 428, in _AddRestoreOps
    assign_ops.append(saveable.restore(saveable_tensors, shapes))
  File "C:\Users\Sjoerd de Jong\anaconda3\envs\tensorFolk\lib\site-packages\tensorflow\python\training\saver.py", line 119, in restore
    self.op.get_shape().is_fully_defined())
  File "C:\Users\Sjoerd de Jong\anaconda3\envs\tensorFolk\lib\site-packages\tensorflow\python\ops\state_ops.py", line 221, in assign
    validate_shape=validate_shape)
  File "C:\Users\Sjoerd de Jong\anaconda3\envs\tensorFolk\lib\site-packages\tensorflow\python\ops\gen_state_ops.py", line 64, in assign
    use_locking=use_locking, name=name)
  File "C:\Users\Sjoerd de Jong\anaconda3\envs\tensorFolk\lib\site-packages\tensorflow\python\framework\op_def_library.py", line 787, in _apply_op_helper
    op_def=op_def)
  File "C:\Users\Sjoerd de Jong\anaconda3\envs\tensorFolk\lib\site-packages\tensorflow\python\util\deprecation.py", line 488, in new_func
    return func(*args, **kwargs)
  File "C:\Users\Sjoerd de Jong\anaconda3\envs\tensorFolk\lib\site-packages\tensorflow\python\framework\ops.py", line 3274, in create_op
    op_def=op_def)
  File "C:\Users\Sjoerd de Jong\anaconda3\envs\tensorFolk\lib\site-packages\tensorflow\python\framework\ops.py", line 1770, in __init__
    self._traceback = tf_stack.extract_stack()

InvalidArgumentError (see above for traceback): Restoring from checkpoint failed. This is most likely due to a mismatch between the current graph and the graph from the checkpoint. Please ensure that you have not altered the graph expected based on the checkpoint. Original error:

Assign requires shapes of both tensors to match. lhs shape= [80,80] rhs shape= [73,73]
	 [[node save/Assign_21 (defined at train_rnn.py:114)  = Assign[T=DT_FLOAT, _class=["loc:@w_emb"], use_locking=true, validate_shape=true, _device="/job:localhost/replica:0/task:0/device:CPU:0"](w_emb/RMSProp_1, save/RestoreV2:27)]]

